Traceback (most recent call last):
  File "/Users/gabriele/opt/miniconda3/envs/seislab/lib/python3.11/site-packages/jupyter_cache/executors/utils.py", line 51, in single_nb_execution
    executenb(
  File "/Users/gabriele/opt/miniconda3/envs/seislab/lib/python3.11/site-packages/nbclient/client.py", line 1204, in execute
    return NotebookClient(nb=nb, resources=resources, km=km, **kwargs).execute()
           ^^^^^^^^^^^^^^^^^^^^^^^^^^^^^^^^^^^^^^^^^^^^^^^^^^^^^^^^^^^^^^^^^^^^^
  File "/Users/gabriele/opt/miniconda3/envs/seislab/lib/python3.11/site-packages/nbclient/util.py", line 84, in wrapped
    return just_run(coro(*args, **kwargs))
           ^^^^^^^^^^^^^^^^^^^^^^^^^^^^^^^
  File "/Users/gabriele/opt/miniconda3/envs/seislab/lib/python3.11/site-packages/nbclient/util.py", line 62, in just_run
    return loop.run_until_complete(coro)
           ^^^^^^^^^^^^^^^^^^^^^^^^^^^^^
  File "/Users/gabriele/opt/miniconda3/envs/seislab/lib/python3.11/asyncio/base_events.py", line 650, in run_until_complete
    return future.result()
           ^^^^^^^^^^^^^^^
  File "/Users/gabriele/opt/miniconda3/envs/seislab/lib/python3.11/contextlib.py", line 222, in __aexit__
    await self.gen.athrow(typ, value, traceback)
  File "/Users/gabriele/opt/miniconda3/envs/seislab/lib/python3.11/site-packages/nbclient/client.py", line 608, in async_setup_kernel
    yield
  File "/Users/gabriele/opt/miniconda3/envs/seislab/lib/python3.11/site-packages/nbclient/client.py", line 663, in async_execute
    await self.async_execute_cell(
  File "/Users/gabriele/opt/miniconda3/envs/seislab/lib/python3.11/site-packages/nbclient/client.py", line 965, in async_execute_cell
    await self._check_raise_for_error(cell, cell_index, exec_reply)
  File "/Users/gabriele/opt/miniconda3/envs/seislab/lib/python3.11/site-packages/nbclient/client.py", line 862, in _check_raise_for_error
    raise CellExecutionError.from_cell_and_msg(cell, exec_reply_content)
nbclient.exceptions.CellExecutionError: An error occurred while executing the following cell:
------------------
%matplotlib inline
from myst_nb import glue
np.set_printoptions(precision=3,suppress=True)
import warnings
warnings.filterwarnings("ignore")

import matplotlib.pyplot as plt
plt.ioff()
------------------

[0;31m---------------------------------------------------------------------------[0m
[0;31mNameError[0m                                 Traceback (most recent call last)
Cell [0;32mIn[2], line 3[0m
[1;32m      1[0m get_ipython()[38;5;241m.[39mrun_line_magic([38;5;124m'[39m[38;5;124mmatplotlib[39m[38;5;124m'[39m, [38;5;124m'[39m[38;5;124minline[39m[38;5;124m'[39m)
[1;32m      2[0m [38;5;28;01mfrom[39;00m [38;5;21;01mmyst_nb[39;00m [38;5;28;01mimport[39;00m glue
[0;32m----> 3[0m [43mnp[49m[38;5;241m.[39mset_printoptions(precision[38;5;241m=[39m[38;5;241m3[39m,suppress[38;5;241m=[39m[38;5;28;01mTrue[39;00m)
[1;32m      4[0m [38;5;28;01mimport[39;00m [38;5;21;01mwarnings[39;00m
[1;32m      5[0m warnings[38;5;241m.[39mfilterwarnings([38;5;124m"[39m[38;5;124mignore[39m[38;5;124m"[39m)

[0;31mNameError[0m: name 'np' is not defined
NameError: name 'np' is not defined

