Traceback (most recent call last):
  File "/Users/gabriele/opt/miniconda3/envs/seislab/lib/python3.11/site-packages/jupyter_cache/executors/utils.py", line 51, in single_nb_execution
    executenb(
  File "/Users/gabriele/opt/miniconda3/envs/seislab/lib/python3.11/site-packages/nbclient/client.py", line 1204, in execute
    return NotebookClient(nb=nb, resources=resources, km=km, **kwargs).execute()
           ^^^^^^^^^^^^^^^^^^^^^^^^^^^^^^^^^^^^^^^^^^^^^^^^^^^^^^^^^^^^^^^^^^^^^
  File "/Users/gabriele/opt/miniconda3/envs/seislab/lib/python3.11/site-packages/nbclient/util.py", line 84, in wrapped
    return just_run(coro(*args, **kwargs))
           ^^^^^^^^^^^^^^^^^^^^^^^^^^^^^^^
  File "/Users/gabriele/opt/miniconda3/envs/seislab/lib/python3.11/site-packages/nbclient/util.py", line 62, in just_run
    return loop.run_until_complete(coro)
           ^^^^^^^^^^^^^^^^^^^^^^^^^^^^^
  File "/Users/gabriele/opt/miniconda3/envs/seislab/lib/python3.11/asyncio/base_events.py", line 650, in run_until_complete
    return future.result()
           ^^^^^^^^^^^^^^^
  File "/Users/gabriele/opt/miniconda3/envs/seislab/lib/python3.11/contextlib.py", line 222, in __aexit__
    await self.gen.athrow(typ, value, traceback)
  File "/Users/gabriele/opt/miniconda3/envs/seislab/lib/python3.11/site-packages/nbclient/client.py", line 608, in async_setup_kernel
    yield
  File "/Users/gabriele/opt/miniconda3/envs/seislab/lib/python3.11/site-packages/nbclient/client.py", line 663, in async_execute
    await self.async_execute_cell(
  File "/Users/gabriele/opt/miniconda3/envs/seislab/lib/python3.11/site-packages/nbclient/client.py", line 965, in async_execute_cell
    await self._check_raise_for_error(cell, cell_index, exec_reply)
  File "/Users/gabriele/opt/miniconda3/envs/seislab/lib/python3.11/site-packages/nbclient/client.py", line 862, in _check_raise_for_error
    raise CellExecutionError.from_cell_and_msg(cell, exec_reply_content)
nbclient.exceptions.CellExecutionError: An error occurred while executing the following cell:
------------------
residues = np.array([arrival.time_residual for _, arrival, _ in picks_arrivals_channels])
modelled_times = data[0]- residues 
fig = lab.plot_data(data,origin=ingv,modelled_times=modelled_times)
------------------

[0;31m---------------------------------------------------------------------------[0m
[0;31mValueError[0m                                Traceback (most recent call last)
Cell [0;32mIn[21], line 2[0m
[1;32m      1[0m residues [38;5;241m=[39m np[38;5;241m.[39marray([arrival[38;5;241m.[39mtime_residual [38;5;28;01mfor[39;00m _, arrival, _ [38;5;129;01min[39;00m picks_arrivals_channels])
[0;32m----> 2[0m modelled_times [38;5;241m=[39m [43mdata[49m[43m[[49m[38;5;241;43m0[39;49m[43m][49m[38;5;241;43m-[39;49m[43m [49m[43mresidues[49m 
[1;32m      3[0m fig [38;5;241m=[39m lab[38;5;241m.[39mplot_data(data,origin[38;5;241m=[39mingv,modelled_times[38;5;241m=[39mmodelled_times)

[0;31mValueError[0m: operands could not be broadcast together with shapes (6,) (56,) 
ValueError: operands could not be broadcast together with shapes (6,) (56,) 

